Thu May 16 00:24:25, Warn:  The field "magnitude_output_on" in "dynamicrupture" was given in the parameter file, but is unknown to SeisSol. 
Thu May 16 00:24:25, Warn:  The field "energy_rate_output_on" in "dynamicrupture" was given in the parameter file, but is unknown to SeisSol. 
mkdir: cannot create directory ‘/hppfs/work/pn49ha/di35poq//step700_smooth7’: File exists
mkdir: cannot create directory ‘/hppfs/work/pn49ha/di35poq//step700_smooth7’: File exists
mkdir: cannot create directory ‘/hppfs/work/pn49ha/di35poq//step700_smooth7’: File exists
mkdir: cannot create directory ‘/hppfs/work/pn49ha/di35poq//step700_smooth7’: File exists
mkdir: cannot create directory ‘/hppfs/work/pn49ha/di35poq//step700_smooth7’: File exists
mkdir: cannot create directory ‘/hppfs/work/pn49ha/di35poq//step700_smooth7’: File exists
mkdir: cannot create directory ‘/hppfs/work/pn49ha/di35poq//step700_smooth7’: File exists
mkdir: cannot create directory ‘/hppfs/work/pn49ha/di35poq//step700_smooth7’: File exists
mkdir: cannot create directory ‘/hppfs/work/pn49ha/di35poq//step700_smooth7’: File exists
mkdir: cannot create directory ‘/hppfs/work/pn49ha/di35poq//step700_smooth7’: File exists
mkdir: cannot create directory ‘/hppfs/work/pn49ha/di35poq//step700_smooth7’: File exists
mkdir: cannot create directory ‘/hppfs/work/pn49ha/di35poq//step700_smooth7’: File exists
mkdir: cannot create directory ‘/hppfs/work/pn49ha/di35poq//step700_smooth7’: File exists
mkdir: cannot create directory ‘/hppfs/work/pn49ha/di35poq//step700_smooth7’: File exists
mkdir: cannot create directory ‘/hppfs/work/pn49ha/di35poq//step700_smooth7’: File exists
mkdir: cannot create directory ‘/hppfs/work/pn49ha/di35poq//step700_smooth7’: File exists
Traceback (most recent call last):
  File "/dss/dsshome1/01/di35poq/.local/bin/seissol_output_extractor", line 8, in <module>
    sys.exit(main())
  File "/dss/dsshome1/01/di35poq/.local/lib/python3.8/site-packages/seissolxdmfwriter/seissol_output_extractor.py", line 143, in main
    sx = SeissolxdmfExtended(args.xdmfFilename)
  File "/dss/dsshome1/01/di35poq/.local/lib/python3.8/site-packages/seissolxdmf/seissolxdmf.py", line 14, in __init__
    with open (xdmfFilename, "r") as fid:
FileNotFoundError: [Errno 2] No such file or directory: 'output-fault.xdmf'
Traceback (most recent call last):
  File "/dss/dsshome1/01/di35poq/.local/bin/seissol_output_extractor", line 8, in <module>
    sys.exit(main())
  File "/dss/dsshome1/01/di35poq/.local/lib/python3.8/site-packages/seissolxdmfwriter/seissol_output_extractor.py", line 143, in main
    sx = SeissolxdmfExtended(args.xdmfFilename)
  File "/dss/dsshome1/01/di35poq/.local/lib/python3.8/site-packages/seissolxdmf/seissolxdmf.py", line 14, in __init__
    with open (xdmfFilename, "r") as fid:
FileNotFoundError: [Errno 2] No such file or directory: 'output-fault.xdmf'
Traceback (most recent call last):
  File "/dss/dsshome1/01/di35poq/.local/bin/seissol_output_extractor", line 8, in <module>
    sys.exit(main())
  File "/dss/dsshome1/01/di35poq/.local/lib/python3.8/site-packages/seissolxdmfwriter/seissol_output_extractor.py", line 143, in main
    sx = SeissolxdmfExtended(args.xdmfFilename)
  File "/dss/dsshome1/01/di35poq/.local/lib/python3.8/site-packages/seissolxdmf/seissolxdmf.py", line 14, in __init__
    with open (xdmfFilename, "r") as fid:
FileNotFoundError: [Errno 2] No such file or directory: 'output-fault.xdmf'
Traceback (most recent call last):
  File "/dss/dsshome1/01/di35poq/.local/bin/seissol_output_extractor", line 8, in <module>
    sys.exit(main())
  File "/dss/dsshome1/01/di35poq/.local/lib/python3.8/site-packages/seissolxdmfwriter/seissol_output_extractor.py", line 143, in main
    sx = SeissolxdmfExtended(args.xdmfFilename)
  File "/dss/dsshome1/01/di35poq/.local/lib/python3.8/site-packages/seissolxdmf/seissolxdmf.py", line 14, in __init__
    with open (xdmfFilename, "r") as fid:
FileNotFoundError: [Errno 2] No such file or directory: 'output-fault.xdmf'
Traceback (most recent call last):
  File "/dss/dsshome1/01/di35poq/.local/bin/seissol_output_extractor", line 8, in <module>
    sys.exit(main())
  File "/dss/dsshome1/01/di35poq/.local/lib/python3.8/site-packages/seissolxdmfwriter/seissol_output_extractor.py", line 143, in main
    sx = SeissolxdmfExtended(args.xdmfFilename)
  File "/dss/dsshome1/01/di35poq/.local/lib/python3.8/site-packages/seissolxdmf/seissolxdmf.py", line 14, in __init__
    with open (xdmfFilename, "r") as fid:
FileNotFoundError: [Errno 2] No such file or directory: 'output-fault.xdmf'
Traceback (most recent call last):
  File "/dss/dsshome1/01/di35poq/.local/bin/seissol_output_extractor", line 8, in <module>
    sys.exit(main())
  File "/dss/dsshome1/01/di35poq/.local/lib/python3.8/site-packages/seissolxdmfwriter/seissol_output_extractor.py", line 143, in main
    sx = SeissolxdmfExtended(args.xdmfFilename)
  File "/dss/dsshome1/01/di35poq/.local/lib/python3.8/site-packages/seissolxdmf/seissolxdmf.py", line 14, in __init__
    with open (xdmfFilename, "r") as fid:
FileNotFoundError: [Errno 2] No such file or directory: 'output-fault.xdmf'
Traceback (most recent call last):
  File "/dss/dsshome1/01/di35poq/.local/bin/seissol_output_extractor", line 8, in <module>
    sys.exit(main())
  File "/dss/dsshome1/01/di35poq/.local/lib/python3.8/site-packages/seissolxdmfwriter/seissol_output_extractor.py", line 143, in main
    sx = SeissolxdmfExtended(args.xdmfFilename)
  File "/dss/dsshome1/01/di35poq/.local/lib/python3.8/site-packages/seissolxdmf/seissolxdmf.py", line 14, in __init__
    with open (xdmfFilename, "r") as fid:
FileNotFoundError: [Errno 2] No such file or directory: 'output-fault.xdmf'
Traceback (most recent call last):
  File "/dss/dsshome1/01/di35poq/.local/bin/seissol_output_extractor", line 8, in <module>
    sys.exit(main())
  File "/dss/dsshome1/01/di35poq/.local/lib/python3.8/site-packages/seissolxdmfwriter/seissol_output_extractor.py", line 143, in main
    sx = SeissolxdmfExtended(args.xdmfFilename)
  File "/dss/dsshome1/01/di35poq/.local/lib/python3.8/site-packages/seissolxdmf/seissolxdmf.py", line 14, in __init__
    with open (xdmfFilename, "r") as fid:
FileNotFoundError: [Errno 2] No such file or directory: 'output-fault.xdmf'
Traceback (most recent call last):
  File "/dss/dsshome1/01/di35poq/.local/bin/seissol_output_extractor", line 8, in <module>
    sys.exit(main())
  File "/dss/dsshome1/01/di35poq/.local/lib/python3.8/site-packages/seissolxdmfwriter/seissol_output_extractor.py", line 143, in main
    sx = SeissolxdmfExtended(args.xdmfFilename)
  File "/dss/dsshome1/01/di35poq/.local/lib/python3.8/site-packages/seissolxdmf/seissolxdmf.py", line 14, in __init__
    with open (xdmfFilename, "r") as fid:
FileNotFoundError: [Errno 2] No such file or directory: 'output-fault.xdmf'
Traceback (most recent call last):
  File "/dss/dsshome1/01/di35poq/.local/bin/seissol_output_extractor", line 8, in <module>
    sys.exit(main())
  File "/dss/dsshome1/01/di35poq/.local/lib/python3.8/site-packages/seissolxdmfwriter/seissol_output_extractor.py", line 143, in main
    sx = SeissolxdmfExtended(args.xdmfFilename)
  File "/dss/dsshome1/01/di35poq/.local/lib/python3.8/site-packages/seissolxdmf/seissolxdmf.py", line 14, in __init__
    with open (xdmfFilename, "r") as fid:
FileNotFoundError: [Errno 2] No such file or directory: 'output-fault.xdmf'
Traceback (most recent call last):
  File "/dss/dsshome1/01/di35poq/.local/bin/seissol_output_extractor", line 8, in <module>
    sys.exit(main())
  File "/dss/dsshome1/01/di35poq/.local/lib/python3.8/site-packages/seissolxdmfwriter/seissol_output_extractor.py", line 143, in main
    sx = SeissolxdmfExtended(args.xdmfFilename)
  File "/dss/dsshome1/01/di35poq/.local/lib/python3.8/site-packages/seissolxdmf/seissolxdmf.py", line 14, in __init__
    with open (xdmfFilename, "r") as fid:
FileNotFoundError: [Errno 2] No such file or directory: 'output-fault.xdmf'
Traceback (most recent call last):
  File "/dss/dsshome1/01/di35poq/.local/bin/seissol_output_extractor", line 8, in <module>
    sys.exit(main())
  File "/dss/dsshome1/01/di35poq/.local/lib/python3.8/site-packages/seissolxdmfwriter/seissol_output_extractor.py", line 143, in main
    sx = SeissolxdmfExtended(args.xdmfFilename)
  File "/dss/dsshome1/01/di35poq/.local/lib/python3.8/site-packages/seissolxdmf/seissolxdmf.py", line 14, in __init__
    with open (xdmfFilename, "r") as fid:
FileNotFoundError: [Errno 2] No such file or directory: 'output-fault.xdmf'
Traceback (most recent call last):
  File "/dss/dsshome1/01/di35poq/.local/bin/seissol_output_extractor", line 8, in <module>
    sys.exit(main())
  File "/dss/dsshome1/01/di35poq/.local/lib/python3.8/site-packages/seissolxdmfwriter/seissol_output_extractor.py", line 143, in main
    sx = SeissolxdmfExtended(args.xdmfFilename)
  File "/dss/dsshome1/01/di35poq/.local/lib/python3.8/site-packages/seissolxdmf/seissolxdmf.py", line 14, in __init__
    with open (xdmfFilename, "r") as fid:
FileNotFoundError: [Errno 2] No such file or directory: 'output-fault.xdmf'
Traceback (most recent call last):
  File "/dss/dsshome1/01/di35poq/.local/bin/seissol_output_extractor", line 8, in <module>
    sys.exit(main())
  File "/dss/dsshome1/01/di35poq/.local/lib/python3.8/site-packages/seissolxdmfwriter/seissol_output_extractor.py", line 143, in main
    sx = SeissolxdmfExtended(args.xdmfFilename)
  File "/dss/dsshome1/01/di35poq/.local/lib/python3.8/site-packages/seissolxdmf/seissolxdmf.py", line 14, in __init__
    with open (xdmfFilename, "r") as fid:
FileNotFoundError: [Errno 2] No such file or directory: 'output-fault.xdmf'
Traceback (most recent call last):
  File "/dss/dsshome1/01/di35poq/.local/bin/seissol_output_extractor", line 8, in <module>
    sys.exit(main())
  File "/dss/dsshome1/01/di35poq/.local/lib/python3.8/site-packages/seissolxdmfwriter/seissol_output_extractor.py", line 143, in main
    sx = SeissolxdmfExtended(args.xdmfFilename)
  File "/dss/dsshome1/01/di35poq/.local/lib/python3.8/site-packages/seissolxdmf/seissolxdmf.py", line 14, in __init__
    with open (xdmfFilename, "r") as fid:
FileNotFoundError: [Errno 2] No such file or directory: 'output-fault.xdmf'
Traceback (most recent call last):
  File "/dss/dsshome1/01/di35poq/.local/bin/seissol_output_extractor", line 8, in <module>
    sys.exit(main())
  File "/dss/dsshome1/01/di35poq/.local/lib/python3.8/site-packages/seissolxdmfwriter/seissol_output_extractor.py", line 143, in main
    sx = SeissolxdmfExtended(args.xdmfFilename)
  File "/dss/dsshome1/01/di35poq/.local/lib/python3.8/site-packages/seissolxdmf/seissolxdmf.py", line 14, in __init__
    with open (xdmfFilename, "r") as fid:
FileNotFoundError: [Errno 2] No such file or directory: 'output-fault.xdmf'
mv: cannot stat '/hppfs/work/pn49ha/di35poq/dynamic-relaxation-outputs/tmp-outputs': No such file or directory
mv: cannot stat '/hppfs/work/pn49ha/di35poq/dynamic-relaxation-outputs/tmp-outputs': No such file or directory
mv: cannot stat '/hppfs/work/pn49ha/di35poq/dynamic-relaxation-outputs/tmp-outputs': No such file or directory
mv: cannot stat '/hppfs/work/pn49ha/di35poq/dynamic-relaxation-outputs/tmp-outputs': No such file or directory
mv: cannot stat '/hppfs/work/pn49ha/di35poq/dynamic-relaxation-outputs/tmp-outputs': No such file or directory
mv: cannot stat '/hppfs/work/pn49ha/di35poq/dynamic-relaxation-outputs/tmp-outputs': No such file or directory
mv: cannot stat '/hppfs/work/pn49ha/di35poq/dynamic-relaxation-outputs/tmp-outputs': No such file or directory
mv: cannot stat '/hppfs/work/pn49ha/di35poq/dynamic-relaxation-outputs/tmp-outputs': No such file or directory
mv: cannot stat '/hppfs/work/pn49ha/di35poq/dynamic-relaxation-outputs/tmp-outputs': No such file or directory
mv: cannot stat '/hppfs/work/pn49ha/di35poq/dynamic-relaxation-outputs/tmp-outputs': No such file or directory
mv: cannot stat '/hppfs/work/pn49ha/di35poq/dynamic-relaxation-outputs/tmp-outputs': No such file or directory
mv: cannot stat '/hppfs/work/pn49ha/di35poq/dynamic-relaxation-outputs/tmp-outputs': No such file or directory
mv: cannot stat '/hppfs/work/pn49ha/di35poq/dynamic-relaxation-outputs/tmp-outputs': No such file or directory
mv: cannot stat '/hppfs/work/pn49ha/di35poq/dynamic-relaxation-outputs/tmp-outputs': No such file or directory
mv: cannot stat '/hppfs/work/pn49ha/di35poq/dynamic-relaxation-outputs/tmp-outputs': No such file or directory
srun: error: i01r01c03s11: task 1: Exited with exit code 1
srun: launch/slurm: _step_signal: Terminating StepId=3385956.1
srun: error: i01r01c04s06: task 8: Exited with exit code 1
srun: error: i01r01c04s08: task 10: Exited with exit code 1
srun: error: i01r01c04s01: task 3: Exited with exit code 1
srun: error: i01r01c03s12: task 2: Exited with exit code 1
srun: error: i01r01c04s11: task 13: Exited with exit code 1
srun: error: i01r01c04s09: task 11: Exited with exit code 1
srun: error: i01r01c04s10: task 12: Exited with exit code 1
srun: error: i01r01c04s07: task 9: Exited with exit code 1
srun: error: i01r01c04s04: task 6: Exited with exit code 1
srun: error: i01r01c04s05: task 7: Exited with exit code 1
srun: error: i01r01c04s03: task 5: Exited with exit code 1
srun: error: i01r01c04s02: task 4: Exited with exit code 1
srun: error: i01r01c04s12: task 14: Exited with exit code 1
srun: error: i01r01c05s01: task 15: Exited with exit code 1
