terminate called after throwing an instance of 'std::runtime_error'
  what():  Haiti_initial_stress.yaml@28: Could not find model for point [ 601334 2.02899e+06 -25225.4 ] in group 68.
srun: error: i01r01c03s03: task 7: Aborted (core dumped)
srun: launch/slurm: _step_signal: Terminating StepId=3413417.0
slurmstepd: error: *** STEP 3413417.0 ON i01r01c02s08 CANCELLED AT 2024-06-11T00:11:09 ***
srun: error: i01r01c02s12: task 4: Terminated
srun: error: i01r01c03s01: task 5: Terminated
srun: error: i01r01c03s10: task 14: Terminated
srun: error: i01r01c03s04: task 8: Terminated
srun: error: i01r01c03s07: task 11: Terminated
srun: error: i01r01c02s08: task 0: Terminated
srun: error: i01r01c03s11: task 15: Terminated
srun: error: i01r01c03s09: task 13: Terminated
srun: error: i01r01c02s09: task 1: Terminated
srun: error: i01r01c02s11: task 3: Terminated
srun: error: i01r01c03s06: task 10: Terminated
srun: error: i01r01c02s10: task 2: Terminated
srun: error: i01r01c03s08: task 12: Terminated
srun: error: i01r01c03s05: task 9: Terminated
srun: error: i01r01c03s02: task 6: Terminated
srun: Force Terminated StepId=3413417.0
